Workbook

Sheet Listed Firms
A1: GSE Non-Financial Listed Firms – Final Sample
A2: Green = included. Yellow = excluded cross-listed multinationals (no standalone Ghana financials). Pink = financial institutions excluded by design.
A4: Symbol | B4: Company | C4: Market | D4: Sector | E4: Classification | F4: Usable Obs. | G4: Study Coverage | H4: Notes
A5: ALW | B5: Aluworks Ltd | C5: Main | D5: Basic Materials | E5: Non-Financial (Included) | F5: 5 | G5: FY2019–FY2023 (base FY2018)
A6: BOPP | B6: Benso Oil Palm Plantation Ltd | C6: Main | D6: Consumer Goods / Agriculture | E6: Non-Financial (Included) | F6: 5 | G6: FY2019–FY2023 (base FY2018)
A7: CLYD | B7: Clydestone (Ghana) Ltd | C7: Main | D7: Technology | E7: Non-Financial (Included) | F7: 5 | G7: FY2019–FY2023 (base FY2018)
A8: CMLT | B8: Camelot Ghana Ltd | C8: Main | D8: Industrials | E8: Non-Financial (Included) | F8: 5 | G8: FY2019–FY2023 (base FY2018)
A9: CPC | B9: Cocoa Processing Company | C9: Main | D9: Consumer Goods | E9: Non-Financial (Included) | F9: 5 | G9: FY2019–FY2023 (base FY2018)
A10: FML | B10: Fan Milk Ltd | C10: Main | D10: Consumer Goods | E10: Non-Financial (Included) | F10: 5 | G10: FY2019–FY2023 (base FY2018)
A11: GGBL | B11: Guinness Ghana Breweries Plc | C11: Main | D11: Consumer Goods | E11: Non-Financial (Included) | F11: 5 | G11: FY2019–FY2023 (base FY2018)
A12: GOIL | B12: GOIL PLC | C12: Main | D12: Oil & Gas | E12: Non-Financial (Included) | F12: 5 | G12: FY2019–FY2023 (base FY2018)
A13: MTNGH | B13: MTN Ghana (Scancom PLC) | C13: Main | D13: Telecom | E13: Non-Financial (Included) | F13: 5 | G13: FY2019–FY2023 (base FY2018)
A14: PBC | B14: Produce Buying Company Ltd | C14: Main | D14: Consumer Goods / Agriculture | E14: Non-Financial (Included) | F14: 5 | G14: FY2019–FY2023 (base FY2018)
A15: TOTAL | B15: TotalEnergies Marketing Ghana PLC | C15: Main | D15: Oil & Gas | E15: Non-Financial (Included) | F15: 5 | G15: FY2019–FY2023 (base FY2018) | H15: Formerly Total Petroleum Ghana Ltd
A16: UNIL | B16: Unilever Ghana PLC | C16: Main | D16: Consumer Goods | E16: Non-Financial (Included) | F16: 5 | G16: FY2019–FY2023 (base FY2018)
A17: DIGICUT | B17: Digicut Advertising & Production Ltd | C17: GAX | D17: Consumer Services | E17: Non-Financial (Included) | F17: 5 | G17: FY2019–FY2023 (base FY2018)
A18: HORDS | B18: Hords Ltd | C18: GAX | D18: Consumer Goods | E18: Non-Financial (Included) | F18: 5 | G18: FY2019–FY2023 (base FY2018)
A19: IIL | B19: Intravenous Infusions PLC | C19: GAX | D19: Health Care | E19: Non-Financial (Included) | F19: 5 | G19: FY2019–FY2023 (base FY2018)
A20: MMH | B20: Meridian-Marshalls Holdings | C20: GAX | D20: Consumer Services | E20: Non-Financial (Included) | F20: 5 | G20: FY2019–FY2023 (base FY2018)
A21: SAMBA | B21: Samba Foods Ltd | C21: GAX | D21: Consumer Goods | E21: Non-Financial (Included) | F21: 5 | G21: FY2019–FY2023 (base FY2018)
A22: MLC | B22: Mechanical Lloyd Plc | C22: Main | D22: Industrials | E22: Non-Financial (Included) | F22: 2 | G22: FY2019–FY2020 (base FY2018) | H22: Delisted 2021
A23: PZC | B23: PZ Cussons Ghana Ltd | C23: Main | D23: Consumer Goods | E23: Non-Financial (Included) | F23: 2 | G23: FY2019–FY2020 (base FY2018) | H23: Delisted Oct 2020
A24: DASPHARMA | B24: Dannex Ayrton Starwin Plc | C24: Main | D24: Health Care / Pharma | E24: Non-Financial (Included) | F24: 3 | G24: FY2021–FY2023 (base FY2020) | H24: Formed Jan 2020; FY2020 = base year only
A25: SWL | B25: Sam Wood Ltd | C25: Main | D25: Consumer Services | E25: Non-Financial (Included) | F25: 2 | G25: FY2019–FY2020 (base FY2018) | H25: Suspended Sept 2020; delisted April 2023
A26: AGA | B26: AngloGold Ashanti Plc | C26: Main | D26: Mining | E26: Excluded – Cross-listed multinational | F26: – | G26: – | H26: Listed via Ghanaian Depositary Shares; no standalone Ghana financials. Global consolidated USD accounts.
A27: TLW | B27: Tullow Oil Plc | C27: Main | D27: Oil & Gas | E27: Excluded – Cross-listed multinational | F27: – | G27: – | H27: Secondary listing of Tullow Oil plc (primary: LSE). No Ghana-only financials; global consolidated USD accounts.
A28: ASG | B28: Asante Gold Corporation | C28: Main | D28: Mining | E28: Excluded – Cross-listed multinational | F28: – | G28: – | H28: Incorporated in British Columbia, Canada; primary listing on CSE. No Ghana-only financials; USD accounts.
A29: ADB | B29: Agricultural Development Bank | C29: Main | D29: Banking | E29: Financial – Excluded | H29: Distinct regulatory/reporting framework
A30: CAL | B30: CalBank PLC | C30: Main | D30: Banking | E30: Financial – Excluded
A31: GCB | B31: GCB Bank Ltd | C31: Main | D31: Banking | E31: Financial – Excluded
A32: EGL | B32: Enterprise Group PLC | C32: Main | D32: Insurance / Holding | E32: Financial – Excluded
A33: SIC | B33: SIC Insurance Company Ltd | C33: Main | D33: Insurance | E33: Financial – Excluded
A35: Legend:
A36: Non-Financial – included in sample
A37: Excluded – cross-listed multinational (no standalone Ghana financials)
A38: Financial institution – excluded by design

Sheet Raw Data Input
A1: Raw Financial Statement Data – Enter Once Per Firm-Year
A2: Blue cells = enter your data. Record the reporting unit (col E) before entering numbers (e.g. GHS ’000 or GHS millions – check the cover page of each annual report). Column U flags if Total Assets ≠ Total Liabilities + Total Equity.
A4: Symbol | B4: Company | C4: Fiscal Year | D4: Key | E4: Reporting Unit | F4: Net Sales / Revenue | G4: Cost of Goods Sold (COGS) | H4: Net Trade Receivables | I4: Current Assets | J4: Net PP&E | K4: Securities / Long-term Invest. | L4: Total Assets | M4: SG&A Expenses | N4: Depreciation & Amortisation | O4: Net Income (continuing ops) | P4: Cash Flow from Operations | Q4: Current Liabilities | R4: Long-term Debt | S4: Total Liabilities | T4: Total Equity | U4: Balance Check (TA−TL−TE)
A5: ALW | B5: Aluworks Ltd | C5: 2018 | D5: =A5&"-"&C5 -> ALW-2018 | E5: GHS’000 | F5: 62495 | G5: -68275 | H5: 555 | I5: 16783 | J5: 213320 | K5: 120 | L5: 230133 | M5: -10609 | N5: 5484 | O5: 33162 | P5: -10161 | Q5: 128850 | R5: 0 | S5: 156448 | T5: 73685 | U5: =IF(OR(L5="",S5="",T5=""),"",L5-S5-T5) -> 0
A6: ALW | B6: Aluworks Ltd | C6: 2019 | D6: =A6&"-"&C6 -> ALW-2019 | E6: GHS’000 | F6: 76993 | G6: -77125 | H6: 737 | I6: 19473 | J6: 206458 | K6: 120 | L6: 226051 | M6: -9257 | N6: 7283 | O6: 24199 | P6: 2760 | Q6: 154993 | R6: 0 | S6: 206309 | T6: 19742 | U6: =IF(OR(L6="",S6="",T6=""),"",L6-S6-T6) -> 0
A7: ALW | B7: Aluworks Ltd | C7: 2020 | D7: =A7&"-"&C7 -> ALW-2020 | E7: GHS’000 | F7: 68975 | G7: -74005 | H7: 400 | I7: 15182 | J7: 200096 | K7: 120 | L7: 215398 | M7: -7327 | N7: 6985 | O7: -33794 | P7: -4834 | Q7: 181036 | R7: 0 | S7: 230081 | T7: -14683 | U7: =IF(OR(L7="",S7="",T7=""),"",L7-S7-T7) -> 0
A8: ALW | B8: Aluworks Ltd | C8: 2021 | D8: =A8&"-"&C8 -> ALW-2021 | E8: GHS’000 | F8: 99011 | G8: -113096 | H8: 641 | I8: 14276 | J8: 217360 | K8: 120 | L8: 236102 | M8: -11666 | N8: 10071 | O8: -65755 | P8: -26944 | Q8: 189271 | R8: 0 | S8: 193621 | T8: 42481 | U8: =IF(OR(L8="",S8="",T8=""),"",L8-S8-T8) -> 0
A9: ALW | B9: Aluworks Ltd | C9: 2022 | D9: =A9&"-"&C9 -> ALW-2022 | E9: GHS’000 | F9: 33441 | G9: -58196 | H9: 1086 | I9: 16352 | J9: 209318 | K9: 0 | L9: 230136 | M9: -10697 | N9: 8071 | O9: -74943 | P9: 473 | Q9: 72289 | R9: 0 | S9: 262598 | T9: -32462 | U9: =IF(OR(L9="",S9="",T9=""),"",L9-S9-T9) -> 0
A10: ALW | B10: Aluworks Ltd | C10: 2023 | D10: =A10&"-"&C10 -> ALW-2023 | F10: 0 | G10: 0 | H10: 0 | I10: 0 | J10: 0 | K10: 0 | L10: 0 | M10: 0 | N10: 0 | O10: 0 | P10: 0 | Q10: 0 | R10: 0 | S10: 0 | T10: 0 | U10: =IF(OR(L10="",S10="",T10=""),"",L10-S10-T10) -> 0
A11: BOPP | B11: Benso Oil Palm Plantation Ltd | C11: 2018 | D11: =A11&"-"&C11 -> BOPP-2018 | E11: GHS’000 | F11: 70091 | G11: -65161 | H11: 1035 | I11: 29376 | J11: 47309 | K11: 0 | L11: 81435 | M11: -9386 | N11: 3644 | O11: 5913 | P11: 11259 | Q11: 8276 | R11: 0 | S11: 13054 | T11: 68381 | U11: =IF(OR(L11="",S11="",T11=""),"",L11-S11-T11) -> 0
A12: BOPP | B12: Benso Oil Palm Plantation Ltd | C12: 2019 | D12: =A12&"-"&C12 -> BOPP-2019 | E12: GHS’000 | F12: 95620 | G12: -76240 | H12: 0 | I12: 38292 | J12: 49471 | K12: 0 | L12: 92900 | M12: -8494 | N12: 3995 | O12: 9653 | P12: 9770 | Q12: 10290 | R12: 0 | S12: 16049 | T12: 76851 | U12: =IF(OR(L12="",S12="",T12=""),"",L12-S12-T12) -> 0
A13: BOPP | B13: Benso Oil Palm Plantation Ltd | C13: 2020 | D13: =A13&"-"&C13 -> BOPP-2020 | E13: GHS’000 | F13: 123817 | G13: -84940 | H13: 0 | I13: 49431 | J13: 57909 | K13: 0 | L13: 119115 | M13: -11727 | N13: 4757 | O13: 24697 | P13: 31347 | Q13: 10087 | R13: 0 | S13: 19481 | T13: 99634 | U13: =IF(OR(L13="",S13="",T13=""),"",L13-S13-T13) -> 0
A14: BOPP | B14: Benso Oil Palm Plantation Ltd | C14: 2021 | D14: =A14&"-"&C14 -> BOPP-2021 | E14: GHS’000 | F14: 214175 | G14: -101397 | H14: 0 | I14: 139104 | J14: 64417 | K14: 0 | L14: 223123 | M14: -14943 | N14: 5570 | O14: 92423 | P14: 35256 | Q14: 30368 | R14: 0 | S14: 38484 | T14: 184639 | U14: =IF(OR(L14="",S14="",T14=""),"",L14-S14-T14) -> 0
A15: BOPP | B15: Benso Oil Palm Plantation Ltd | C15: 2022 | D15: =A15&"-"&C15 -> BOPP-2022 | E15: GHS’000 | F15: 340496 | G15: -157865 | H15: 0 | I15: 197444 | J15: 95446 | K15: 0 | L15: 324730 | M15: -23345 | N15: 7092 | O15: 160354 | P15: 126476 | Q15: 44818 | R15: 0 | S15: 55999 | T15: 268731 | U15: =IF(OR(L15="",S15="",T15=""),"",L15-S15-T15) -> 0
A16: BOPP | B16: Benso Oil Palm Plantation Ltd | C16: 2023 | D16: =A16&"-"&C16 -> BOPP-2023 | E16: GHS’000 | F16: 351611 | G16: -220401 | H16: 0 | I16: 184352 | J16: 136833 | K16: 0 | L16: 369175 | M16: -31843 | N16: 10714 | O16: 102813 | P16: 180308 | Q16: 61933 | R16: 0 | S16: 77292 | T16: 291883 | U16: =IF(OR(L16="",S16="",T16=""),"",L16-S16-T16) -> 0
A17: CLYD | B17: Clydestone (Ghana) Ltd | C17: 2018 | D17: =A17&"-"&C17 -> CLYD-2018 | E17: GHS | F17: 5861359 | G17: -4244824 | H17: 2284453 | I17: 3755240 | J17: 311659 | K17: 3100 | L17: 5339861 | M17: 1159536 | N17: 119081 | O17: 576293 | P17: 202856 | Q17: 2213142 | R17: 0 | S17: 4759677 | T17: 580184 | U17: =IF(OR(L17="",S17="",T17=""),"",L17-S17-T17) -> 0
A18: CLYD | B18: Clydestone (Ghana) Ltd | C18: 2019 | D18: =A18&"-"&C18 -> CLYD-2019 | E18: GHS | F18: 7244821 | G18: -5322352 | H18: 2083907 | I18: 3935378 | J18: 235519 | K18: 0 | L18: 5441358 | M18: 1187033 | N18: 90072 | O18: 224284 | P18: 448938 | Q18: 3174611 | R18: 0 | S18: 4395995 | T18: 1045363 | U18: =IF(OR(L18="",S18="",T18=""),"",L18-S18-T18) -> 0
A19: CLYD | B19: Clydestone (Ghana) Ltd | C19: 2020 | D19: =A19&"-"&C19 -> CLYD-2020 | E19: GHS | F19: 4039375 | G19: -2358952 | H19: 1990637 | I19: 3080302 | J19: 162051 | K19: 24536 | L19: 6592549 | M19: 1107547 | N19: 86948 | O19: 72139 | P19: 215325 | Q19: 4759677 | R19: 0 | S19: 3450920 | T19: 3141629 | U19: =IF(OR(L19="",S19="",T19=""),"",L19-S19-T19) -> 0
A20: CLYD | B20: Clydestone (Ghana) Ltd | C20: 2021 | D20: =A20&"-"&C20 -> CLYD-2021 | E20: GHS | F20: 2496111 | G20: -1456770 | H20: 1464738 | I20: 2706870 | J20: 85875 | K20: -3100 | L20: 6213658 | M20: 853015 | N20: 80160 | O20: -424863 | P20: -308177 | Q20: 4758528 | R20: 0 | S20: 3525033 | T20: 2886839 | U20: =IF(OR(L20="",S20="",T20=""),"",L20-S20-T20) -> -198214
A21: CLYD | B21: Clydestone (Ghana) Ltd | C21: 2022 | D21: =A21&"-"&C21 -> CLYD-2022 | E21: GHS | F21: 8037301 | G21: -5207385.2 | H21: 4049439.1 | I21: 6772740.7 | J21: 654920.21 | K21: 0 | L21: 10905418 | M21: 2110896.8 | N21: 24164.31 | O21: 571109.99 | P21: 242792.83 | Q21: 6487756.2 | R21: 555555.58 | S21: 7043311.8 | T21: 3862106.1 | U21: =IF(OR(L21="",S21="",T21=""),"",L21-S21-T21) -> 0.467
A22: CLYD | B22: Clydestone (Ghana) Ltd | C22: 2023 | D22: =A22&"-"&C22 -> CLYD-2023 | E22: GHS | F22: 7336525.5 | G22: -3665826.8 | H22: 2802250.3 | I22: 5619732.9 | J22: 632662.53 | K22: 0 | L22: 9820242.2 | M22: 2541494.3 | N22: 46971.36 | O22: 134251.03 | P22: -1388100 | Q22: 4953866.6 | R22: 870018.8 | S22: 5823885.4 | T22: 3996357.1 | U22: =IF(OR(L22="",S22="",T22=""),"",L22-S22-T22) -> -0.32
... A108: MLC | B108: Mechanical Lloyd Plc | C108: 2019 | D108: =A108&"-"&C108 -> MLC-2019 | E108: GHS | F108: 21918273 | G108: -16180849 | H108: 6017753 | I108: 22485264 | J108: 33572917 | K108: 0 | L108: 58470276 | M108: -7665070 | N108: 0 | O108: -2688819 | P108: -310003 | Q108: 27896776 | R108: 0 | S108: 30756716 | T108: 27713561 | U108: =IF(OR(L108="",S108="",T108=""),"",L108-S108-T108) -> -1
A109: MLC | B109: Mechanical Lloyd Plc | C109: 2020 | D109: =A109&"-"&C109 -> MLC-2020 | E109: GHS | F109: 9970882 | G109: -8250141 | H109: 14933576 | I109: 24966906 | J109: 97764847 | L109: 131100529 | M109: -4542329 | N109: 0 | O109: -3959508 | P109: 1150112 | Q109: 34028342 | R109: 0 | S109: 55476483 | T109: 75624046 | U109: =IF(OR(L109="",S109="",T109=""),"",L109-S109-T109) -> 0
A110: PZC | B110: PZ Cussons Ghana Ltd | C110: 2018 | D110: =A110&"-"&C110 -> PZC-2018 | E110: GHS | F110: 111603488 | G110: -83870319 | H110: 0 | I110: 51984793 | J110: 7108672 | K110: 1405271 | L110: 93844816 | M110: -11242366 | N110: 0 | O110: 6480638 | P110: -11920953 | Q110: 45526907 | R110: 24646442 | S110: 71952827 | T110: 21891989 | U110: =IF(OR(L110="",S110="",T110=""),"",L110-S110-T110) -> 0
A111: PZC | B111: PZ Cussons Ghana Ltd | C111: 2019 | D111: =A111&"-"&C111 -> PZC-2019 | E111: GHS | F111: 106517018 | G111: -81461330 | H111: 0 | I111: 55540228 | J111: 4485770 | K111: 0 | L111: 133483230 | M111: -9774488 | N111: 0 | O111: 42495592 | P111: 2581812 | Q111: 26046393 | R111: 27949781 | S111: 69095649 | T111: 64387581 | U111: =IF(OR(L111="",S111="",T111=""),"",L111-S111-T111) -> 0
A112: PZC | B112: PZ Cussons Ghana Ltd | C112: 2020 | D112: =A112&"-"&C112 -> PZC-2020 | E112: GHS | F112: 0 | G112: 0 | H112: 0 | I112: 0 | J112: 0 | K112: 0 | L112: 0 | M112: 0 | N112: 0 | O112: 0 | P112: 0 | Q112: 0 | R112: 0 | S112: 0 | T112: 0 | U112: =IF(OR(L112="",S112="",T112=""),"",L112-S112-T112) -> 0
A113: DASPHARMA | B113: Dannex Ayrton Starwin Plc | C113: 2020 | D113: =A113&"-"&C113 -> DASPHARMA-2020 | E113: GHS | F113: 65918628 | G113: -36631759 | H113: 12978051 | I113: 28262785 | J113: 21211854 | K113: 2416650 | L113: 54042877 | M113: -31592320 | N113: 1924361 | O113: -5158244 | P113: 2196318 | Q113: 25549507 | R113: 14656190 | S113: 47257238 | T113: 6785639 | U113: =IF(OR(L113="",S113="",T113=""),"",L113-S113-T113) -> 0
A114: DASPHARMA | B114: Dannex Ayrton Starwin Plc | C114: 2021 | D114: =A114&"-"&C114 -> DASPHARMA-2021 | E114: GHS | F114: 74530831 | G114: -35543875 | H114: 14782153 | I114: 35861605 | J114: 21211034 | K114: 2416650 | L114: 63567078 | M114: -33197332 | N114: 2167643 | O114: 4881672 | P114: 276489 | Q114: 32981425 | R114: 13203189 | S114: 51899767 | T114: 11667311 | U114: =IF(OR(L114="",S114="",T114=""),"",L114-S114-T114) -> 0
A115: DASPHARMA | B115: Dannex Ayrton Starwin Plc | C115: 2022 | D115: =A115&"-"&C115 -> DASPHARMA-2022 | E115: GHS | F115: 95792613 | G115: -45070953 | H115: 14609803 | I115: 42084059 | J115: 25651135 | K115: 2416650 | L115: 75150272 | M115: -51166681 | N115: 2432827 | O115: -3451029 | P115: 7908599 | Q115: 42711447 | R115: 17176758 | S115: 66933990 | T115: 8216282 | U115: =IF(OR(L115="",S115="",T115=""),"",L115-S115-T115) -> 0
A116: DASPHARMA | B116: Dannex Ayrton Starwin Plc | C116: 2023 | D116: =A116&"-"&C116 -> DASPHARMA-2023 | E116: GHS | F116: 141003384 | G116: -63546084 | H116: 14038862 | I116: 51187402 | J116: 25165512 | K116: 0 | L116: 78217554 | M116: -61111160 | N116: 2613655 | O116: 7553731 | P116: 14092506 | Q116: 42431143 | R116: 10544326 | S116: 61867528 | T116: 16350026 | U116: =IF(OR(L116="",S116="",T116=""),"",L116-S116-T116) -> 0
A117: SWL | B117: Sam Wood Ltd | C117: 2018 | D117: =A117&"-"&C117 -> SWL-2018 | E117: GHS | F117: 1052688 | G117: -593129 | H117: 5286 | I117: 600588 | J117: 3290274 | K117: 0 | L117: 4263538 | M117: -1286415 | N117: 467428 | O117: -1471127 | P117: -786252 | Q117: 3718636 | R117: 0 | S117: 3906745 | T117: 356793 | U117: =IF(OR(L117="",S117="",T117=""),"",L117-S117-T117) -> 0
A118: SWL | B118: Sam Wood Ltd | C118: 2019 | D118: =A118&"-"&C118 -> SWL-2019 | E118: GHS | F118: 454180 | G118: -424377 | H118: 4124 | I118: 545971 | J118: 3025809 | K118: 0 | L118: 3914988 | M118: -813627 | N118: 378867 | O118: -1265083 | P118: -478025 | Q118: 4635169 | R118: 0 | S118: 4823278 | T118: -908290 | U118: =IF(OR(L118="",S118="",T118=""),"",L118-S118-T118) -> 0
A119: SWL | B119: Sam Wood Ltd | C119: 2020 | D119: =A119&"-"&C119 -> SWL-2020 | E119: GHS | F119: 0 | G119: -506148 | H119: 4124 | I119: 397150 | J119: 2758815 | K119: 0 | L119: 3396210 | M119: -27516 | N119: 369956 | O119: -533664 | P119: -592 | Q119: 4650055 | R119: 0 | S119: 4838164 | T119: -1441954 | U119: =IF(OR(L119="",S119="",T119=""),"",L119-S119-T119) -> 0
A121: Legend:
A122: Grey = base year only (needed for prior-year comparison, not itself an M-Score observation)
A123: Green = usable M-Score year
A124: Blue text = enter your data | Black text = automatic formula, do not edit

Sheet Lookups
A1: Internal Helper Sheet – Do Not Edit
A2: Pulls current-year (t) and prior-year (t−1) raw data for every usable M-Score row. All cells are formulas.
A4: Symbol | B4: Company | C4: Fiscal Year | D4: Current Key | E4: Prior Key | F4: Sales_t | G4: COGS_t | H4: Receiv_t | I4: CurrAssets_t | J4: PPE_t | K4: Securities_t | L4: TotalAssets_t | M4: SGA_t | N4: Deprec_t | O4: NetIncome_t | P4: CFO_t | Q4: CurrLiab_t | R4: LTDebt_t | S4: TotalLiab_t | T4: TotalEquity_t | U4: Sales_t-1 | V4: COGS_t-1 | W4: Receiv_t-1 | X4: CurrAssets_t-1 | Y4: PPE_t-1 | Z4: Securities_t-1 | AA4: TotalAssets_t-1 | AB4: SGA_t-1 | AC4: Deprec_t-1 | AD4: NetIncome_t-1 | AE4: CFO_t-1 | AF4: CurrLiab_t-1 | AG4: LTDebt_t-1 | AH4: TotalLiab_t-1 | AI4: TotalEquity_t-1
A5: ALW | B5: Aluworks Ltd | C5: 2019 | D5: =A5&"-"&C5 -> ALW-2019 | E5: =A5&"-"&(C5-1) -> ALW-2018 | F5: =IFERROR(INDEX('Raw Data Input'!$F:$F,MATCH($D5,'Raw Data Input'!$D:$D,0)),0) -> 76993 | G5: =IFERROR(INDEX('Raw Data Input'!$G:$G,MATCH($D5,'Raw Data Input'!$D:$D,0)),0) -> -77125 | H5: =IFERROR(INDEX('Raw Data Input'!$H:$H,MATCH($D5,'Raw Data Input'!$D:$D,0)),0) -> 737 | I5: =IFERROR(INDEX('Raw Data Input'!$I:$I,MATCH($D5,'Raw Data Input'!$D:$D,0)),0) -> 19473 | J5: =IFERROR(INDEX('Raw Data Input'!$J:$J,MATCH($D5,'Raw Data Input'!$D:$D,0)),0) -> 206458 | K5: =IFERROR(INDEX('Raw Data Input'!$K:$K,MATCH($D5,'Raw Data Input'!$D:$D,0)),0) -> 120 | L5: =IFERROR(INDEX('Raw Data Input'!$L:$L,MATCH($D5,'Raw Data Input'!$D:$D,0)),0) -> 226051 | M5: =IFERROR(INDEX('Raw Data Input'!$M:$M,MATCH($D5,'Raw Data Input'!$D:$D,0)),0) -> -9257 | N5: =IFERROR(INDEX('Raw Data Input'!$N:$N,MATCH($D5,'Raw Data Input'!$D:$D,0)),0) -> 7283 | O5: =IFERROR(INDEX('Raw Data Input'!$O:$O,MATCH($D5,'Raw Data Input'!$D:$D,0)),0) -> 24199 | P5: =IFERROR(INDEX('Raw Data Input'!$P:$P,MATCH($D5,'Raw Data Input'!$D:$D,0)),0) -> 2760 | Q5: =IFERROR(INDEX('Raw Data Input'!$Q:$Q,MATCH($D5,'Raw Data Input'!$D:$D,0)),0) -> 154993 | R5: =IFERROR(INDEX('Raw Data Input'!$R:$R,MATCH($D5,'Raw Data Input'!$D:$D,0)),0) -> 0 | S5: =IFERROR(INDEX('Raw Data Input'!$S:$S,MATCH($D5,'Raw Data Input'!$D:$D,0)),0) -> 206309 | T5: =IFERROR(INDEX('Raw Data Input'!$T:$T,MATCH($D5,'Raw Data Input'!$D:$D,0)),0) -> 19742 | U5: =IFERROR(INDEX('Raw Data Input'!$F:$F,MATCH($E5,'Raw Data Input'!$D:$D,0)),0) -> 62495 | V5: =IFERROR(INDEX('Raw Data Input'!$G:$G,MATCH($E5,'Raw Data Input'!$D:$D,0)),0) -> -68275 | W5: =IFERROR(INDEX('Raw Data Input'!$H:$H,MATCH($E5,'Raw Data Input'!$D:$D,0)),0) -> 555 | X5: =IFERROR(INDEX('Raw Data Input'!$I:$I,MATCH($E5,'Raw Data Input'!$D:$D,0)),0) -> 16783 | Y5: =IFERROR(INDEX('Raw Data Input'!$J:$J,MATCH($E5,'Raw Data Input'!$D:$D,0)),0) -> 213320 | Z5: =IFERROR(INDEX('Raw Data Input'!$K:$K,MATCH($E5,'Raw Data Input'!$D:$D,0)),0) -> 120 | AA5: =IFERROR(INDEX('Raw Data Input'!$L:$L,MATCH($E5,'Raw Data Input'!$D:$D,0)),0) -> 230133 | AB5: =IFERROR(INDEX('Raw Data Input'!$M:$M,MATCH($E5,'Raw Data Input'!$D:$D,0)),0) -> -10609 | AC5: =IFERROR(INDEX('Raw Data Input'!$N:$N,MATCH($E5,'Raw Data Input'!$D:$D,0)),0) -> 5484 | AD5: =IFERROR(INDEX('Raw Data Input'!$O:$O,MATCH($E5,'Raw Data Input'!$D:$D,0)),0) -> 33162 | AE5: =IFERROR(INDEX('Raw Data Input'!$P:$P,MATCH($E5,'Raw Data Input'!$D:$D,0)),0) -> -10161 | AF5: =IFERROR(INDEX('Raw Data Input'!$Q:$Q,MATCH($E5,'Raw Data Input'!$D:$D,0)),0) -> 128850 | AG5: =IFERROR(INDEX('Raw Data Input'!$R:$R,MATCH($E5,'Raw Data Input'!$D:$D,0)),0) -> 0 | AH5: =IFERROR(INDEX('Raw Data Input'!$S:$S,MATCH($E5,'Raw Data Input'!$D:$D,0)),0) -> 156448 | AI5: =IFERROR(INDEX('Raw Data Input'!$T:$T,MATCH($E5,'Raw Data Input'!$D:$D,0)),0) -> 73685
A6: ALW | B6: Aluworks Ltd | C6: 2020 | D6: =A6&"-"&C6 -> ALW-2020 | E6: =A6&"-"&(C6-1) -> ALW-2019 | F6: =IFERROR(INDEX('Raw Data Input'!$F:$F,MATCH($D6,'Raw Data Input'!$D:$D,0)),0) -> 68975 | G6: =IFERROR(INDEX('Raw Data Input'!$G:$G,MATCH($D6,'Raw Data Input'!$D:$D,0)),0) -> -74005 | H6: =IFERROR(INDEX('Raw Data Input'!$H:$H,MATCH($D6,'Raw Data Input'!$D:$D,0)),0) -> 400 | I6: =IFERROR(INDEX('Raw Data Input'!$I:$I,MATCH($D6,'Raw Data Input'!$D:$D,0)),0) -> 15182 | J6: =IFERROR(INDEX('Raw Data Input'!$J:$J,MATCH($D6,'Raw Data Input'!$D:$D,0)),0) -> 200096 | K6: =IFERROR(INDEX('Raw Data Input'!$K:$K,MATCH($D6,'Raw Data Input'!$D:$D,0)),0) -> 120 | L6: =IFERROR(INDEX('Raw Data Input'!$L:$L,MATCH($D6,'Raw Data Input'!$D:$D,0)),0) -> 215398 | M6: =IFERROR(INDEX('Raw Data Input'!$M:$M,MATCH($D6,'Raw Data Input'!$D:$D,0)),0) -> -7327 | N6: =IFERROR(INDEX('Raw Data Input'!$N:$N,MATCH($D6,'Raw Data Input'!$D:$D,0)),0) -> 6985 | O6: =IFERROR(INDEX('Raw Data Input'!$O:$O,MATCH($D6,'Raw Data Input'!$D:$D,0)),0) -> -33794 | P6: =IFERROR(INDEX('Raw Data Input'!$P:$P,MATCH($D6,'Raw Data Input'!$D:$D,0)),0) -> -4834 | Q6: =IFERROR(INDEX('Raw Data Input'!$Q:$Q,MATCH($D6,'Raw Data Input'!$D:$D,0)),0) -> 181036 | R6: =IFERROR(INDEX('Raw Data Input'!$R:$R,MATCH($D6,'Raw Data Input'!$D:$D,0)),0) -> 0 | S6: =IFERROR(INDEX('Raw Data Input'!$S:$S,MATCH($D6,'Raw Data Input'!$D:$D,0)),0) -> 230081 | T6: =IFERROR(INDEX('Raw Data Input'!$T:$T,MATCH($D6,'Raw Data Input'!$D:$D,0)),0) -> -14683 | U6: =IFERROR(INDEX('Raw Data Input'!$F:$F,MATCH($E6,'Raw Data Input'!$D:$D,0)),0) -> 76993 | V6: =IFERROR(INDEX('Raw Data Input'!$G:$G,MATCH($E6,'Raw Data Input'!$D:$D,0)),0) -> -77125 | W6: =IFERROR(INDEX('Raw Data Input'!$H:$H,MATCH($E6,'Raw Data Input'!$D:$D,0)),0) -> 737 | X6: =IFERROR(INDEX('Raw Data Input'!$I:$I,MATCH($E6,'Raw Data Input'!$D:$D,0)),0) -> 19473 | Y6: =IFERROR(INDEX('Raw Data Input'!$J:$J,MATCH($E6,'Raw Data Input'!$D:$D,0)),0) -> 206458 | Z6: =IFERROR(INDEX('Raw Data Input'!$K:$K,MATCH($E6,'Raw Data Input'!$D:$D,0)),0) -> 120 | AA6: =IFERROR(INDEX('Raw Data Input'!$L:$L,MATCH($E6,'Raw Data Input'!$D:$D,0)),0) -> 226051 | AB6: =IFERROR(INDEX('Raw Data Input'!$M:$M,MATCH($E6,'Raw Data Input'!$D:$D,0)),0) -> -9257 | AC6: =IFERROR(INDEX('Raw Data Input'!$N:$N,MATCH($E6,'Raw Data Input'!$D:$D,0)),0) -> 7283 | AD6: =IFERROR(INDEX('Raw Data Input'!$O:$O,MATCH($E6,'Raw Data Input'!$D:$D,0)),0) -> 24199 | AE6: =IFERROR(INDEX('Raw Data Input'!$P:$P,MATCH($E6,'Raw Data Input'!$D:$D,0)),0) -> 2760 | AF6: =IFERROR(INDEX('Raw Data Input'!$Q:$Q,MATCH($E6,'Raw Data Input'!$D:$D,0)),0) -> 154993 | AG6: =IFERROR(INDEX('Raw Data Input'!$R:$R,MATCH($E6,'Raw Data Input'!$D:$D,0)),0) -> 0 | AH6: =IFERROR(INDEX('Raw Data Input'!$S:$S,MATCH($E6,'Raw Data Input'!$D:$D,0)),0) -> 206309 | AI6: =IFERROR(INDEX('Raw Data Input'!$T:$T,MATCH($E6,'Raw Data Input'!$D:$D,0)),0) -> 19742
A7: ALW | B7: Aluworks Ltd | C7: 2021 | D7: =A7&"-"&C7 -> ALW-2021 | E7: =A7&"-"&(C7-1) -> ALW-2020 | F7: =IFERROR(INDEX('Raw Data Input'!$F:$F,MATCH($D7,'Raw Data Input'!$D:$D,0)),0) -> 99011 | G7: =IFERROR(INDEX('Raw Data Input'!$G:$G,MATCH($D7,'Raw Data Input'!$D:$D,0)),0) -> -113096 | H7: =IFERROR(INDEX('Raw Data Input'!$H:$H,MATCH($D7,'Raw Data Input'!$D:$D,0)),0) -> 641 | I7: =IFERROR(INDEX('Raw Data Input'!$I:$I,MATCH($D7,'Raw Data Input'!$D:$D,0)),0) -> 14276 | J7: =IFERROR(INDEX('Raw Data Input'!$J:$J,MATCH($D7,'Raw Data Input'!$D:$D,0)),0) -> 217360 | K7: =IFERROR(INDEX('Raw Data Input'!$K:$K,MATCH($D7,'Raw Data Input'!$D:$D,0)),0) -> 120 | L7: =IFERROR(INDEX('Raw Data Input'!$L:$L,MATCH($D7,'Raw Data Input'!$D:$D,0)),0) -> 236102 | M7: =IFERROR(INDEX('Raw Data Input'!$M:$M,MATCH($D7,'Raw Data Input'!$D:$D,0)),0) -> -11666 | N7: =IFERROR(INDEX('Raw Data Input'!$N:$N,MATCH($D7,'Raw Data Input'!$D:$D,0)),0) -> 10071 | O7: =IFERROR(INDEX('Raw Data Input'!$O:$O,MATCH($D7,'Raw Data Input'!$D:$D,0)),0) -> -65755 | P7: =IFERROR(INDEX('Raw Data Input'!$P:$P,MATCH($D7,'Raw Data Input'!$D:$D,0)),0) -> -26944 | Q7: =IFERROR(INDEX('Raw Data Input'!$Q:$Q,MATCH($D7,'Raw Data Input'!$D:$D,0)),0) -> 189271 | R7: =IFERROR(INDEX('Raw Data Input'!$R:$R,MATCH($D7,'Raw Data Input'!$D:$D,0)),0) -> 0 | S7: =IFERROR(INDEX('Raw Data Input'!$S:$S,MATCH($D7,'Raw Data Input'!$D:$D,0)),0) -> 193621 | T7: =IFERROR(INDEX('Raw Data Input'!$T:$T,MATCH($D7,'Raw Data Input'!$D:$D,0)),0) -> 42481 | U7: =IFERROR(INDEX('Raw Data Input'!$F:$F,MATCH($E7,'Raw Data Input'!$D:$D,0)),0) -> 68975 | V7: =IFERROR(INDEX('Raw Data Input'!$G:$G,MATCH($E7,'Raw Data Input'!$D:$D,0)),0) -> -74005 | W7: =IFERROR(INDEX('Raw Data Input'!$H:$H,MATCH($E7,'Raw Data Input'!$D:$D,0)),0) -> 400 | X7: =IFERROR(INDEX('Raw Data Input'!$I:$I,MATCH($E7,'Raw Data Input'!$D:$D,0)),0) -> 15182 | Y7: =IFERROR(INDEX('Raw Data Input'!$J:$J,MATCH($E7,'Raw Data Input'!$D:$D,0)),0) -> 200096 | Z7: =IFERROR(INDEX('Raw Data Input'!$K:$K,MATCH($E7,'Raw Data Input'!$D:$D,0)),0) -> 120 | AA7: =IFERROR(INDEX('Raw Data Input'!$L:$L,MATCH($E7,'Raw Data Input'!$D:$D,0)),0) -> 215398 | AB7: =IFERROR(INDEX('Raw Data Input'!$M:$M,MATCH($E7,'Raw Data Input'!$D:$D,0)),0) -> -7327 | AC7: =IFERROR(INDEX('Raw Data Input'!$N:$N,MATCH($E7,'Raw Data Input'!$D:$D,0)),0) -> 6985 | AD7: =IFERROR(INDEX('Raw Data Input'!$O:$O,MATCH($E7,'Raw Data Input'!$D:$D,0)),0) -> -33794 | AE7: =IFERROR(INDEX('Raw Data Input'!$P:$P,MATCH($E7,'Raw Data Input'!$D:$D,0)),0) -> -4834 | AF7: =IFERROR(INDEX('Raw Data Input'!$Q:$Q,MATCH($E7,'Raw Data Input'!$D:$D,0)),0) -> 181036 | AG7: =IFERROR(INDEX('Raw Data Input'!$R:$R,MATCH($E7,'Raw Data Input'!$D:$D,0)),0) -> 0 | AH7: =IFERROR(INDEX('Raw Data Input'!$S:$S,MATCH($E7,'Raw Data Input'!$D:$D,0)),0) -> 230081 | AI7: =IFERROR(INDEX('Raw Data Input'!$T:$T,MATCH($E7,'Raw Data Input'!$D:$D,0)),0) -> -14683
A8: ALW | B8: Aluworks Ltd | C8: 2022 | D8: =A8&"-"&C8 -> ALW-2022 | E8: =A8&"-"&(C8-1) -> ALW-2021 | F8: =IFERROR(INDEX('Raw Data Input'!$F:$F,MATCH($D8,'Raw Data Input'!$D:$D,0)),0) -> 33441 | G8: =IFERROR(INDEX('Raw Data Input'!$G:$G,MATCH($D8,'Raw Data Input'!$D:$D,0)),0) -> -58196 | H8: =IFERROR(INDEX('Raw Data Input'!$H:$H,MATCH($D8,'Raw Data Input'!$D:$D,0)),0) -> 1086 | I8: =IFERROR(INDEX('Raw Data Input'!$I:$I,MATCH($D8,'Raw Data Input'!$D:$D,0)),0) -> 16352 | J8: =IFERROR(INDEX('Raw Data Input'!$J:$J,MATCH($D8,'Raw Data Input'!$D:$D,0)),0) -> 209318 | K8: =IFERROR(INDEX('Raw Data Input'!$K:$K,MATCH($D8,'Raw Data Input'!$D:$D,0)),0) -> 0 | L8: =IFERROR(INDEX('Raw Data Input'!$L:$L,MATCH($D8,'Raw Data Input'!$D:$D,0)),0) -> 230136 | M8: =IFERROR(INDEX('Raw Data Input'!$M:$M,MATCH($D8,'Raw Data Input'!$D:$D,0)),0) -> -10697 | N8: =IFERROR(INDEX('Raw Data Input'!$N:$N,MATCH($D8,'Raw Data Input'!$D:$D,0)),0) -> 8071 | O8: =IFERROR(INDEX('Raw Data Input'!$O:$O,MATCH($D8,'Raw Data Input'!$D:$D,0)),0) -> -74943 | P8: =IFERROR(INDEX('Raw Data Input'!$P:$P,MATCH($D8,'Raw Data Input'!$D:$D,0)),0) -> 473 | Q8: =IFERROR(INDEX('Raw Data Input'!$Q:$Q,MATCH($D8,'Raw Data Input'!$D:$D,0)),0) -> 72289 | R8: =IFERROR(INDEX('Raw Data Input'!$R:$R,MATCH($D8,'Raw Data Input'!$D:$D,0)),0) -> 0 | S8: =IFERROR(INDEX('Raw Data Input'!$S:$S,MATCH($D8,'Raw Data Input'!$D:$D,0)),0) -> 262598 | T8: =IFERROR(INDEX('Raw Data Input'!$T:$T,MATCH($D8,'Raw Data Input'!$D:$D,0)),0) -> -32462 | U8: =IFERROR(INDEX('Raw Data Input'!$F:$F,MATCH($E8,'Raw Data Input'!$D:$D,0)),0) -> 99011 | V8: =IFERROR(INDEX('Raw Data Input'!$G:$G,MATCH($E8,'Raw Data Input'!$D:$D,0)),0) -> -113096 | W8: =IFERROR(INDEX('Raw Data Input'!$H:$H,MATCH($E8,'Raw Data Input'!$D:$D,0)),0) -> 641 | X8: =IFERROR(INDEX('Raw Data Input'!$I:$I,MATCH($E8,'Raw Data Input'!$D:$D,0)),0) -> 14276 | Y8: =IFERROR(INDEX('Raw Data Input'!$J:$J,MATCH($E8,'Raw Data Input'!$D:$D,0)),0) -> 217360 | Z8: =IFERROR(INDEX('Raw Data Input'!$K:$K,MATCH($E8,'Raw Data Input'!$D:$D,0)),0) -> 120 | AA8: =IFERROR(INDEX('Raw Data Input'!$L:$L,MATCH($E8,'Raw Data Input'!$D:$D,0)),0) -> 236102 | AB8: =IFERROR(INDEX('Raw Data Input'!$M:$M,MATCH($E8,'Raw Data Input'!$D:$D,0)),0) -> -11666 | AC8: =IFERROR(INDEX('Raw Data Input'!$N:$N,MATCH($E8,'Raw Data Input'!$D:$D,0)),0) -> 10071 | AD8: =IFERROR(INDEX('Raw Data Input'!$O:$O,MATCH($E8,'Raw Data Input'!$D:$D,0)),0) -> -65755 | AE8: =IFERROR(INDEX('Raw Data Input'!$P:$P,MATCH($E8,'Raw Data Input'!$D:$D,0)),0) -> -26944 | AF8: =IFERROR(INDEX('Raw Data Input'!$Q:$Q,MATCH($E8,'Raw Data Input'!$D:$D,0)),0) -> 189271 | AG8: =IFERROR(INDEX('Raw Data Input'!$R:$R,MATCH($E8,'Raw Data Input'!$D:$D,0)),0) -> 0 | AH8: =IFERROR(INDEX('Raw Data Input'!$S:$S,MATCH($E8,'Raw Data Input'!$D:$D,0)),0) -> 193621 | AI8: =IFERROR(INDEX('Raw Data Input'!$T:$T,MATCH($E8,'Raw Data Input'!$D:$D,0)),0) -> 42481
A9: ALW | B9: Aluworks Ltd | C9: 2023 | D9: =A9&"-"&C9 -> ALW-2023 | E9: =A9&"-"&(C9-1) -> ALW-2022 | F9: =IFERROR(INDEX('Raw Data Input'!$F:$F,MATCH($D9,'Raw Data Input'!$D:$D,0)),0) -> 0 | G9: =IFERROR(INDEX('Raw Data Input'!$G:$G,MATCH($D9,'Raw Data Input'!$D:$D,0)),0) -> 0 | H9: =IFERROR(INDEX('Raw Data Input'!$H:$H,MATCH($D9,'Raw Data Input'!$D:$D,0)),0) -> 0 | I9: =IFERROR(INDEX('Raw Data Input'!$I:$I,MATCH($D9,'Raw Data Input'!$D:$D,0)),0) -> 0 | J9: =IFERROR(INDEX('Raw Data Input'!$J:$J,MATCH($D9,'Raw Data Input'!$D:$D,0)),0) -> 0 | K9: =IFERROR(INDEX('Raw Data Input'!$K:$K,MATCH($D9,'Raw Data Input'!$D:$D,0)),0) -> 0 | L9: =IFERROR(INDEX('Raw Data Input'!$L:$L,MATCH($D9,'Raw Data Input'!$D:$D,0)),0) -> 0 | M9: =IFERROR(INDEX('Raw Data Input'!$M:$M,MATCH($D9,'Raw Data Input'!$D:$D,0)),0) -> 0 | N9: =IFERROR(INDEX('Raw Data Input'!$N:$N,MATCH($D9,'Raw Data Input'!$D:$D,0)),0) -> 0 | O9: =IFERROR(INDEX('Raw Data Input'!$O:$O,MATCH($D9,'Raw Data Input'!$D:$D,0)),0) -> 0 | P9: =IFERROR(INDEX('Raw Data Input'!$P:$P,MATCH($D9,'Raw Data Input'!$D:$D,0)),0) -> 0 | Q9: =IFERROR(INDEX('Raw Data Input'!$Q:$Q,MATCH($D9,'Raw Data Input'!$D:$D,0)),0) -> 0 | R9: =IFERROR(INDEX('Raw Data Input'!$R:$R,MATCH($D9,'Raw Data Input'!$D:$D,0)),0) -> 0 | S9: =IFERROR(INDEX('Raw Data Input'!$S:$S,MATCH($D9,'Raw Data Input'!$D:$D,0)),0) -> 0 | T9: =IFERROR(INDEX('Raw Data Input'!$T:$T,MATCH($D9,'Raw Data Input'!$D:$D,0)),0) -> 0 | U9: =IFERROR(INDEX('Raw Data Input'!$F:$F,MATCH($E9,'Raw Data Input'!$D:$D,0)),0) -> 33441 | V9: =IFERROR(INDEX('Raw Data Input'!$G:$G,MATCH($E9,'Raw Data Input'!$D:$D,0)),0) -> -58196 | W9: =IFERROR(INDEX('Raw Data Input'!$H:$H,MATCH($E9,'Raw Data Input'!$D:$D,0)),0) -> 1086 | X9: =IFERROR(INDEX('Raw Data Input'!$I:$I,MATCH($E9,'Raw Data Input'!$D:$D,0)),0) -> 16352 | Y9: =IFERROR(INDEX('Raw Data Input'!$J:$J,MATCH($E9,'Raw Data Input'!$D:$D,0)),0) -> 209318 | Z9: =IFERROR(INDEX('Raw Data Input'!$K:$K,MATCH($E9,'Raw Data Input'!$D:$D,0)),0) -> 0 | AA9: =IFERROR(INDEX('Raw Data Input'!$L:$L,MATCH($E9,'Raw Data Input'!$D:$D,0)),0) -> 230136 | AB9: =IFERROR(INDEX('Raw Data Input'!$M:$M,MATCH($E9,'Raw Data Input'!$D:$D,0)),0) -> -10697 | AC9: =IFERROR(INDEX('Raw Data Input'!$N:$N,MATCH($E9,'Raw Data Input'!$D:$D,0)),0) -> 8071 | AD9: =IFERROR(INDEX('Raw Data Input'!$O:$O,MATCH($E9,'Raw Data Input'!$D:$D,0)),0) -> -74943 | AE9: =IFERROR(INDEX('Raw Data Input'!$P:$P,MATCH($E9,'Raw Data Input'!$D:$D,0)),0) -> 473 | AF9: =IFERROR(INDEX('Raw Data Input'!$Q:$Q,MATCH($E9,'Raw Data Input'!$D:$D,0)),0) -> 72289 | AG9: =IFERROR(INDEX('Raw Data Input'!$R:$R,MATCH($E9,'Raw Data Input'!$D:$D,0)),0) -> 0 | AH9: =IFERROR(INDEX('Raw Data Input'!$S:$S,MATCH($E9,'Raw Data Input'!$D:$D,0)),0) -> 262598 | AI9: =IFERROR(INDEX('Raw Data Input'!$T:$T,MATCH($E9,'Raw Data Input'!$D:$D,0)),0) -> -32462
A10: BOPP | B10: Benso Oil Palm Plantation Ltd | C10: 2019 | D10: =A10&"-"&C10 -> BOPP-2019 | E10: =A10&"-"&(C10-1) -> BOPP-2018 | F10: =IFERROR(INDEX('Raw Data Input'!$F:$F,MATCH($D10,'Raw Data Input'!$D:$D,0)),0) -> 95620 | G10: =IFERROR(INDEX('Raw Data Input'!$G:$G,MATCH($D10,'Raw Data Input'!$D:$D,0)),0) -> -76240 | H10: =IFERROR(INDEX('Raw Data Input'!$H:$H,MATCH($D10,'Raw Data Input'!$D:$D,0)),0) -> 0 | I10: =IFERROR(INDEX('Raw Data Input'!$I:$I,MATCH($D10,'Raw Data Input'!$D:$D,0)),0) -> 38292 | J10: =IFERROR(INDEX('Raw Data Input'!$J:$J,MATCH($D10,'Raw Data Input'!$D:$D,0)),0) -> 49471 | K10: =IFERROR(INDEX('Raw Data Input'!$K:$K,MATCH($D10,'Raw Data Input'!$D:$D,0)),0) -> 0 | L10: =IFERROR(INDEX('Raw Data Input'!$L:$L,MATCH($D10,'Raw Data Input'!$D:$D,0)),0) -> 92900 | M10: =IFERROR(INDEX('Raw Data Input'!$M:$M,MATCH($D10,'Raw Data Input'!$D:$D,0)),0) -> -8494 | N10: =IFERROR(INDEX('Raw Data Input'!$N:$N,MATCH($D10,'Raw Data Input'!$D:$D,0)),0) -> 3995 | O10: =IFERROR(INDEX('Raw Data Input'!$O:$O,MATCH($D10,'Raw Data Input'!$D:$D,0)),0) -> 9653 | P10: =IFERROR(INDEX('Raw Data Input'!$P:$P,MATCH($D10,'Raw Data Input'!$D:$D,0)),0) -> 9770 | Q10: =IFERROR(INDEX('Raw Data Input'!$Q:$Q,MATCH($D10,'Raw Data Input'!$D:$D,0)),0) -> 10290 | R10: =IFERROR(INDEX('Raw Data Input'!$R:$R,MATCH($D10,'Raw Data Input'!$D:$D,0)),0) -> 0 | S10: =IFERROR(INDEX('Raw Data Input'!$S:$S,MATCH($D10,'Raw Data Input'!$D:$D,0)),0) -> 16049 | T10: =IFERROR(INDEX('Raw Data Input'!$T:$T,MATCH($D10,'Raw Data Input'!$D:$D,0)),0) -> 76851 | U10: =IFERROR(INDEX('Raw Data Input'!$F:$F,MATCH($E10,'Raw Data Input'!$D:$D,0)),0) -> 70091 | V10: =IFERROR(INDEX('Raw Data Input'!$G:$G,MATCH($E10,'Raw Data Input'!$D:$D,0)),0) -> -65161 | W10: =IFERROR(INDEX('Raw Data Input'!$H:$H,MATCH($E10,'Raw Data Input'!$D:$D,0)),0) -> 1035 | X10: =IFERROR(INDEX('Raw Data Input'!$I:$I,MATCH($E10,'Raw Data Input'!$D:$D,0)),0) -> 29376 | Y10: =IFERROR(INDEX('Raw Data Input'!$J:$J,MATCH($E10,'Raw Data Input'!$D:$D,0)),0) -> 47309 | Z10: =IFERROR(INDEX('Raw Data Input'!$K:$K,MATCH($E10,'Raw Data Input'!$D:$D,0)),0) -> 0 | AA10: =IFERROR(INDEX('Raw Data Input'!$L:$L,MATCH($E10,'Raw Data Input'!$D:$D,0)),0) -> 81435 | AB10: =IFERROR(INDEX('Raw Data Input'!$M:$M,MATCH($E10,'Raw Data Input'!$D:$D,0)),0) -> -9386 | AC10: =IFERROR(INDEX('Raw Data Input'!$N:$N,MATCH($E10,'Raw Data Input'!$D:$D,0)),0) -> 3644 | AD10: =IFERROR(INDEX('Raw Data Input'!$O:$O,MATCH($E10,'Raw Data Input'!$D:$D,0)),0) -> 5913 | AE10: =IFERROR(INDEX('Raw Data Input'!$P:$P,MATCH($E10,'Raw Data Input'!$D:$D,0)),0) -> 11259 | AF10: =IFERROR(INDEX('Raw Data Input'!$Q:$Q,MATCH($E10,'Raw Data Input'!$D:$D,0)),0) -> 8276 | AG10: =IFERROR(INDEX('Raw Data Input'!$R:$R,MATCH($E10,'Raw Data Input'!$D:$D,0)),0) -> 0 | AH10: =IFERROR(INDEX('Raw Data Input'!$S:$S,MATCH($E10,'Raw Data Input'!$D:$D,0)),0) -> 13054 | AI10: =IFERROR(INDEX('Raw Data Input'!$T:$T,MATCH($E10,'Raw Data Input'!$D:$D,0)),0) -> 68381
A11: BOPP | B11: Benso Oil Palm Plantation Ltd | C11: 2020 | D11: =A11&"-"&C11 -> BOPP-2020 | E11: =A11&"-"&(C11-1) -> BOPP-2019 | F11: =IFERROR(INDEX('Raw Data Input'!$F:$F,MATCH($D11,'Raw Data Input'!$D:$D,0)),0) -> 123817 | G11: =IFERROR(INDEX('Raw Data Input'!$G:$G,MATCH($D11,'Raw Data Input'!$D:$D,0)),0) -> -84940 | H11: =IFERROR(INDEX('Raw Data Input'!$H:$H,MATCH($D11,'Raw Data Input'!$D:$D,0)),0) -> 0 | I11: =IFERROR(INDEX('Raw Data Input'!$I:$I,MATCH($D11,'Raw Data Input'!$D:$D,0)),0) -> 49431 | J11: =IFERROR(INDEX('Raw Data Input'!$J:$J,MATCH($D11,'Raw Data Input'!$D:$D,0)),0) -> 57909 | K11: =IFERROR(INDEX('Raw Data Input'!$K:$K,MATCH($D11,'Raw Data Input'!$D:$D,0)),0) -> 0 | L11: =IFERROR(INDEX('Raw Data Input'!$L:$L,MATCH($D11,'Raw Data Input'!$D:$D,0)),0) -> 119115 | M11: =IFERROR(INDEX('Raw Data Input'!$M:$M,MATCH($D11,'Raw Data Input'!$D:$D,0)),0) -> -11727 | N11: =IFERROR(INDEX('Raw Data Input'!$N:$N,MATCH($D11,'Raw Data Input'!$D:$D,0)),0) -> 4757 | O11: =IFERROR(INDEX('Raw Data Input'!$O:$O,MATCH($D11,'Raw Data Input'!$D:$D,0)),0) -> 24697 | P11: =IFERROR(INDEX('Raw Data Input'!$P:$P,MATCH($D11,'Raw Data Input'!$D:$D,0)),0) -> 31347 | Q11: =IFERROR(INDEX('Raw Data Input'!$Q:$Q,MATCH($D11,'Raw Data Input'!$D:$D,0)),0) -> 10087 | R11: =IFERROR(INDEX('Raw Data Input'!$R:$R,MATCH($D11,'Raw Data Input'!$D:$D,0)),0) -> 0 | S11: =IFERROR(INDEX('Raw Data Input'!$S:$S,MATCH($D11,'Raw Data Input'!$D:$D,0)),0) -> 19481 | T11: =IFERROR(INDEX('Raw Data Input'!$T:$T,MATCH($D11,'Raw Data Input'!$D:$D,0)),0) -> 99634 | U11: =IFERROR(INDEX('Raw Data Input'!$F:$F,MATCH($E11,'Raw Data Input'!$D:$D,0)),0) -> 95620 | V11: =IFERROR(INDEX('Raw Data Input'!$G:$G,MATCH($E11,'Raw Data Input'!$D:$D,0)),0) -> -76240 | W11: =IFERROR(INDEX('Raw Data Input'!$H:$H,MATCH($E11,'Raw Data Input'!$D:$D,0)),0) -> 0 | X11: =IFERROR(INDEX('Raw Data Input'!$I:$I,MATCH($E11,'Raw Data Input'!$D:$D,0)),0) -> 38292 | Y11: =IFERROR(INDEX('Raw Data Input'!$J:$J,MATCH($E11,'Raw Data Input'!$D:$D,0)),0) -> 49471 | Z11: =IFERROR(INDEX('Raw Data Input'!$K:$K,MATCH($E11,'Raw Data Input'!$D:$D,0)),0) -> 0 | AA11: =IFERROR(INDEX('Raw Data Input'!$L:$L,MATCH($E11,'Raw Data Input'!$D:$D,0)),0) -> 92900 | AB11: =IFERROR(INDEX('Raw Data Input'!$M:$M,MATCH($E11,'Raw Data Input'!$D:$D,0)),0) -> -8494 | AC11: =IFERROR(INDEX('Raw Data Input'!$N:$N,MATCH($E11,'Raw Data Input'!$D:$D,0)),0) -> 3995 | AD11: =IFERROR(INDEX('Raw Data Input'!$O:$O,MATCH($E11,'Raw Data Input'!$D:$D,0)),0) -> 9653 | AE11: =IFERROR(INDEX('Raw Data Input'!$P:$P,MATCH($E11,'Raw Data Input'!$D:$D,0)),0) -> 9770 | AF11: =IFERROR(INDEX('Raw Data Input'!$Q:$Q,MATCH($E11,'Raw Data Input'!$D:$D,0)),0) -> 10290 | AG11: =IFERROR(INDEX('Raw Data Input'!$R:$R,MATCH($E11,'Raw Data Input'!$D:$D,0)),0) -> 0 | AH11: =IFERROR(INDEX('Raw Data Input'!$S:$S,MATCH($E11,'Raw Data Input'!$D:$D,0)),0) -> 16049 | AI11: =IFERROR(INDEX('Raw Data Input'!$T:$T,MATCH($E11,'Raw Data Input'!$D:$D,0)),0) -> 76851
A12: BOPP | B12: Benso Oil Palm Plantation Ltd | C12: 2021 | D12: =A12&"-"&C12 -> BOPP-2021 | E12: =A12&"-"&(C12-1) -> BOPP-2020 | F12: =IFERROR(INDEX('Raw Data Input'!$F:$F,MATCH($D12,'Raw Data Input'!$D:$D,0)),0) -> 214175 | G12: =IFERROR(INDEX('Raw Data Input'!$G:$G,MATCH($D12,'Raw Data Input'!$D:$D,0)),0) -> -101397 | H12: =IFERROR(INDEX('Raw Data Input'!$H:$H,MATCH($D12,'Raw Data Input'!$D:$D,0)),0) -> 0 | I12: =IFERROR(INDEX('Raw Data Input'!$I:$I,MATCH($D12,'Raw Data Input'!$D:$D,0)),0) -> 139104 | J12: =IFERROR(INDEX('Raw Data Input'!$J:$J,MATCH($D12,'Raw Data Input'!$D:$D,0)),0) -> 64417 | K12: =IFERROR(INDEX('Raw Data Input'!$K:$K,MATCH($D12,'Raw Data Input'!$D:$D,0)),0) -> 0 | L12: =IFERROR(INDEX('Raw Data Input'!$L:$L,MATCH($D12,'Raw Data Input'!$D:$D,0)),0) -> 223123 | M12: =IFERROR(INDEX('Raw Data Input'!$M:$M,MATCH($D12,'Raw Data Input'!$D:$D,0)),0) -> -14943 | N12: =IFERROR(INDEX('Raw Data Input'!$N:$N,MATCH($D12,'Raw Data Input'!$D:$D,0)),0) -> 5570 | O12: =IFERROR(INDEX('Raw Data Input'!$O:$O,MATCH($D12,'Raw Data Input'!$D:$D,0)),0) -> 92423 | P12: =IFERROR(INDEX('Raw Data Input'!$P:$P,MATCH($D12,'Raw Data Input'!$D:$D,0)),0) -> 35256 | Q12: =IFERROR(INDEX('Raw Data Input'!$Q:$Q,MATCH($D12,'Raw Data Input'!$D:$D,0)),0) -> 30368 | R12: =IFERROR(INDEX('Raw Data Input'!$R:$R,MATCH($D12,'Raw Data Input'!$D:$D,0)),0) -> 0 | S12: =IFERROR(INDEX('Raw Data Input'!$S:$S,MATCH($D12,'Raw Data Input'!$D:$D,0)),0) -> 38484 | T12: =IFERROR(INDEX('Raw Data Input'!$T:$T,MATCH($D12,'Raw Data Input'!$D:$D,0)),0) -> 184639 | U12: =IFERROR(INDEX('Raw Data Input'!$F:$F,MATCH($E12,'Raw Data Input'!$D:$D,0)),0) -> 123817 | V12: =IFERROR(INDEX('Raw Data Input'!$G:$G,MATCH($E12,'Raw Data Input'!$D:$D,0)),0) -> -84940 | W12: =IFERROR(INDEX('Raw Data Input'!$H:$H,MATCH($E12,'Raw Data Input'!$D:$D,0)),0) -> 0 | X12: =IFERROR(INDEX('Raw Data Input'!$I:$I,MATCH($E12,'Raw Data Input'!$D:$D,0)),0) -> 49431 | Y12: =IFERROR(INDEX('Raw Data Input'!$J:$J,MATCH($E12,'Raw Data Input'!$D:$D,0)),0) -> 57909 | Z12: =IFERROR(INDEX('Raw Data Input'!$K:$K,MATCH($E12,'Raw Data Input'!$D:$D,0)),0) -> 0 | AA12: =IFERROR(INDEX('Raw Data Input'!$L:$L,MATCH($E12,'Raw Data Input'!$D:$D,0)),0) -> 119115 | AB12: =IFERROR(INDEX('Raw Data Input'!$M:$M,MATCH($E12,'Raw Data Input'!$D:$D,0)),0) -> -11727 | AC12: =IFERROR(INDEX('Raw Data Input'!$N:$N,MATCH($E12,'Raw Data Input'!$D:$D,0)),0) -> 4757 | AD12: =IFERROR(INDEX('Raw Data Input'!$O:$O,MATCH($E12,'Raw Data Input'!$D:$D,0)),0) -> 24697 | AE12: =IFERROR(INDEX('Raw Data Input'!$P:$P,MATCH($E12,'Raw Data Input'!$D:$D,0)),0) -> 31347 | AF12: =IFERROR(INDEX('Raw Data Input'!$Q:$Q,MATCH($E12,'Raw Data Input'!$D:$D,0)),0) -> 10087 | AG12: =IFERROR(INDEX('Raw Data Input'!$R:$R,MATCH($E12,'Raw Data Input'!$D:$D,0)),0) -> 0 | AH12: =IFERROR(INDEX('Raw Data Input'!$S:$S,MATCH($E12,'Raw Data Input'!$D:$D,0)),0) -> 19481 | AI12: =IFERROR(INDEX('Raw Data Input'!$T:$T,MATCH($E12,'Raw Data Input'!$D:$D,0)),0) -> 99634
A13: BOPP | B13: Benso Oil Palm Plantation Ltd | C13: 2022 | D13: =A13&"-"&C13 -> BOPP-2022 | E13: =A13&"-"&(C13-1) -> BOPP-2021 | F13: =IFERROR(INDEX('Raw Data Input'!$F:$F,MATCH($D13,'Raw Data Input'!$D:$D,0)),0) -> 340496 | G13: =IFERROR(INDEX('Raw Data Input'!$G:$G,MATCH($D13,'Raw Data Input'!$D:$D,0)),0) -> -157865 | H13: =IFERROR(INDEX('Raw Data Input'!$H:$H,MATCH($D13,'Raw Data Input'!$D:$D,0)),0) -> 0 | I13: =IFERROR(INDEX('Raw Data Input'!$I:$I,MATCH($D13,'Raw Data Input'!$D:$D,0)),0) -> 197444 | J13: =IFERROR(INDEX('Raw Data Input'!$J:$J,MATCH($D13,'Raw Data Input'!$D:$D,0)),0) -> 95446 | K13: =IFERROR(INDEX('Raw Data Input'!$K:$K,MATCH($D13,'Raw Data Input'!$D:$D,0)),0) -> 0 | L13: =IFERROR(INDEX('Raw Data Input'!$L:$L,MATCH($D13,'Raw Data Input'!$D:$D,0)),0) -> 324730 | M13: =IFERROR(INDEX('Raw Data Input'!$M:$M,MATCH($D13,'Raw Data Input'!$D:$D,0)),0) -> -23345 | N13: =IFERROR(INDEX('Raw Data Input'!$N:$N,MATCH($D13,'Raw Data Input'!$D:$D,0)),0) -> 7092 | O13: =IFERROR(INDEX('Raw Data Input'!$O:$O,MATCH($D13,'Raw Data Input'!$D:$D,0)),0) -> 160354 | P13: =IFERROR(INDEX('Raw Data Input'!$P:$P,MATCH($D13,'Raw Data Input'!$D:$D,0)),0) -> 126476 | Q13: =IFERROR(INDEX('Raw Data Input'!$Q:$Q,MATCH($D13,'Raw Data Input'!$D:$D,0)),0) -> 44818 | R13: =IFERROR(INDEX('Raw Data Input'!$R:$R,MATCH($D13,'Raw Data Input'!$D:$D,0)),0) -> 0 | S13: =IFERROR(INDEX('Raw Data Input'!$S:$S,MATCH($D13,'Raw Data Input'!$D:$D,0)),0) -> 55999 | T13: =IFERROR(INDEX('Raw Data Input'!$T:$T,MATCH($D13,'Raw Data Input'!$D:$D,0)),0) -> 268731 | U13: =IFERROR(INDEX('Raw Data Input'!$F:$F,MATCH($E13,'Raw Data Input'!$D:$D,0)),0) -> 214175 | V13: =IFERROR(INDEX('Raw Data Input'!$G:$G,MATCH($E13,'Raw Data Input'!$D:$D,0)),0) -> -101397 | W13: =IFERROR(INDEX('Raw Data Input'!$H:$H,MATCH($E13,'Raw Data Input'!$D:$D,0)),0) -> 0 | X13: =IFERROR(INDEX('Raw Data Input'!$I:$I,MATCH($E13,'Raw Data Input'!$D:$D,0)),0) -> 139104 | Y13: =IFERROR(INDEX('Raw Data Input'!$J:$J,MATCH($E13,'Raw Data Input'!$D:$D,0)),0) -> 64417 | Z13: =IFERROR(INDEX('Raw Data Input'!$K:$K,MATCH($E13,'Raw Data Input'!$D:$D,0)),0) -> 0 | AA13: =IFERROR(INDEX('Raw Data Input'!$L:$L,MATCH($E13,'Raw Data Input'!$D:$D,0)),0) -> 223123 | AB13: =IFERROR(INDEX('Raw Data Input'!$M:$M,MATCH($E13,'Raw Data Input'!$D:$D,0)),0) -> -14943 | AC13: =IFERROR(INDEX('Raw Data Input'!$N:$N,MATCH($E13,'Raw Data Input'!$D:$D,0)),0) -> 5570 | AD13: =IFERROR(INDEX('Raw Data Input'!$O:$O,MATCH($E13,'Raw Data Input'!$D:$D,0)),0) -> 92423 | AE13: =IFERROR(INDEX('Raw Data Input'!$P:$P,MATCH($E13,'Raw Data Input'!$D:$D,0)),0) -> 35256 | AF13: =IFERROR(INDEX('Raw Data Input'!$Q:$Q,MATCH($E13,'Raw Data Input'!$D:$D,0)),0) -> 30368 | AG13: =IFERROR(INDEX('Raw Data Input'!$R:$R,MATCH($E13,'Raw Data Input'!$D:$D,0)),0) -> 0 | AH13: =IFERROR(INDEX('Raw Data Input'!$S:$S,MATCH($E13,'Raw Data Input'!$D:$D,0)),0) -> 38484 | AI13: =IFERROR(INDEX('Raw Data Input'!$T:$T,MATCH($E13,'Raw Data Input'!$D:$D,0)),0) -> 184639
A14: BOPP | B14: Benso Oil Palm Plantation Ltd | C14: 2023 | D14: =A14&"-"&C14 -> BOPP-2023 | E14: =A14&"-"&(C14-1) -> BOPP-2022 | F14: =IFERROR(INDEX('Raw Data Input'!$F:$F,MATCH($D14,'Raw Data Input'!$D:$D,0)),0) -> 351611 | G14: =IFERROR(INDEX('Raw Data Input'!$G:$G,MATCH($D14,'Raw Data Input'!$D:$D,0)),0) -> -220401 | H14: =IFERROR(INDEX('Raw Data Input'!$H:$H,MATCH($D14,'Raw Data Input'!$D:$D,0)),0) -> 0 | I14: =IFERROR(INDEX('Raw Data Input'!$I:$I,MATCH($D14,'Raw Data Input'!$D:$D,0)),0) -> 184352 | J14: =IFERROR(INDEX('Raw Data Input'!$J:$J,MATCH($D14,'Raw Data Input'!$D:$D,0)),0) -> 136833 | K14: =IFERROR(INDEX('Raw Data Input'!$K:$K,MATCH($D14,'Raw Data Input'!$D:$D,0)),0) -> 0 | L14: =IFERROR(INDEX('Raw Data Input'!$L:$L,MATCH($D14,'Raw Data Input'!$D:$D,0)),0) -> 369175 | M14: =IFERROR(INDEX('Raw Data Input'!$M:$M,MATCH($D14,'Raw Data Input'!$D:$D,0)),0) -> -31843 | N14: =IFERROR(INDEX('Raw Data Input'!$N:$N,MATCH($D14,'Raw Data Input'!$D:$D,0)),0) -> 10714 | O14: =IFERROR(INDEX('Raw Data Input'!$O:$O,MATCH($D14,'Raw Data Input'!$D:$D,0)),0) -> 102813 | P14: =IFERROR(INDEX('Raw Data Input'!$P:$P,MATCH($D14,'Raw Data Input'!$D:$D,0)),0) -> 180308 | Q14: =IFERROR(INDEX('Raw Data Input'!$Q:$Q,MATCH($D14,'Raw Data Input'!$D:$D,0)),0) -> 61933 | R14: =IFERROR(INDEX('Raw Data Input'!$R:$R,MATCH($D14,'Raw Data Input'!$D:$D,0)),0) -> 0 | S14: =IFERROR(INDEX('Raw Data Input'!$S:$S,MATCH($D14,'Raw Data Input'!$D:$D,0)),0) -> 77292 | T14: =IFERROR(INDEX('Raw Data Input'!$T:$T,MATCH($D14,'Raw Data Input'!$D:$D,0)),0) -> 291883 | U14: =IFERROR(INDEX('Raw Data Input'!$F:$F,MATCH($E14,'Raw Data Input'!$D:$D,0)),0) -> 340496 | V14: =IFERROR(INDEX('Raw Data Input'!$G:$G,MATCH($E14,'Raw Data Input'!$D:$D,0)),0) -> -157865 | W14: =IFERROR(INDEX('Raw Data Input'!$H:$H,MATCH($E14,'Raw Data Input'!$D:$D,0)),0) -> 0 | X14: =IFERROR(INDEX('Raw Data Input'!$I:$I,MATCH($E14,'Raw Data Input'!$D:$D,0)),0) -> 197444 | Y14: =IFERROR(INDEX('Raw Data Input'!$J:$J,MATCH($E14,'Raw Data Input'!$D:$D,0)),0) -> 95446 | Z14: =IFERROR(INDEX('Raw Data Input'!$K:$K,MATCH($E14,'Raw Data Input'!$D:$D,0)),0) -> 0 | AA14: =IFERROR(INDEX('Raw Data Input'!$L:$L,MATCH($E14,'Raw Data Input'!$D:$D,0)),0) -> 324730 | AB14: =IFERROR(INDEX('Raw Data Input'!$M:$M,MATCH($E14,'Raw Data Input'!$D:$D,0)),0) -> -23345 | AC14: =IFERROR(INDEX('Raw Data Input'!$N:$N,MATCH($E14,'Raw Data Input'!$D:$D,0)),0) -> 7092 | AD14: =IFERROR(INDEX('Raw Data Input'!$O:$O,MATCH($E14,'Raw Data Input'!$D:$D,0)),0) -> 160354 | AE14: =IFERROR(INDEX('Raw Data Input'!$P:$P,MATCH($E14,'Raw Data Input'!$D:$D,0)),0) -> 126476 | AF14: =IFERROR(INDEX('Raw Data Input'!$Q:$Q,MATCH($E14,'Raw Data Input'!$D:$D,0)),0) -> 44818 | AG14: =IFERROR(INDEX('Raw Data Input'!$R:$R,MATCH($E14,'Raw Data Input'!$D:$D,0)),0) -> 0 | AH14: =IFERROR(INDEX('Raw Data Input'!$S:$S,MATCH($E14,'Raw Data Input'!$D:$D,0)),0) -> 55999 | AI14: =IFERROR(INDEX('Raw Data Input'!$T:$T,MATCH($E14,'Raw Data Input'!$D:$D,0)),0) -> 268731
A15: CLYD | B15: Clydestone (Ghana) Ltd | C15: 2019 | D15: =A15&"-"&C15 -> CLYD-2019 | E15: =A15&"-"&(C15-1) -> CLYD-2018 | F15: =IFERROR(INDEX('Raw Data Input'!$F:$F,MATCH($D15,'Raw Data Input'!$D:$D,0)),0) -> 7244821 | G15: =IFERROR(INDEX('Raw Data Input'!$G:$G,MATCH($D15,'Raw Data Input'!$D:$D,0)),0) -> -5322352 | H15: =IFERROR(INDEX('Raw Data Input'!$H:$H,MATCH($D15,'Raw Data Input'!$D:$D,0)),0) -> 2083907 | I15: =IFERROR(INDEX('Raw Data Input'!$I:$I,MATCH($D15,'Raw Data Input'!$D:$D,0)),0) -> 3935378 | J15: =IFERROR(INDEX('Raw Data Input'!$J:$J,MATCH($D15,'Raw Data Input'!$D:$D,0)),0) -> 235519 | K15: =IFERROR(INDEX('Raw Data Input'!$K:$K,MATCH($D15,'Raw Data Input'!$D:$D,0)),0) -> 0 | L15: =IFERROR(INDEX('Raw Data Input'!$L:$L,MATCH($D15,'Raw Data Input'!$D:$D,0)),0) -> 5441358 | M15: =IFERROR(INDEX('Raw Data Input'!$M:$M,MATCH($D15,'Raw Data Input'!$D:$D,0)),0) -> 1187033 | N15: =IFERROR(INDEX('Raw Data Input'!$N:$N,MATCH($D15,'Raw Data Input'!$D:$D,0)),0) -> 90072 | O15: =IFERROR(INDEX('Raw Data Input'!$O:$O,MATCH($D15,'Raw Data Input'!$D:$D,0)),0) -> 224284 | P15: =IFERROR(INDEX('Raw Data Input'!$P:$P,MATCH($D15,'Raw Data Input'!$D:$D,0)),0) -> 448938 | Q15: =IFERROR(INDEX('Raw Data Input'!$Q:$Q,MATCH($D15,'Raw Data Input'!$D:$D,0)),0) -> 3174611 | R15: =IFERROR(INDEX('Raw Data Input'!$R:$R,MATCH($D15,'Raw Data Input'!$D:$D,0)),0) -> 0 | S15: =IFERROR(INDEX('Raw Data Input'!$S:$S,MATCH($D15,'Raw Data Input'!$D:$D,0)),0) -> 4395995 | T15: =IFERROR(INDEX('Raw Data Input'!$T:$T,MATCH($D15,'Raw Data Input'!$D:$D,0)),0) -> 1045363 | U15: =IFERROR(INDEX('Raw Data Input'!$F:$F,MATCH($E15,'Raw Data Input'!$D:$D,0)),0) -> 5861359 | V15: =IFERROR(INDEX('Raw Data Input'!$G:$G,MATCH($E15,'Raw Data Input'!$D:$D,0)),0) -> -4244824 | W15: =IFERROR(INDEX('Raw Data Input'!$H:$H,MATCH($E15,'Raw Data Input'!$D:$D,0)),0) -> 2284453 | X15: =IFERROR(INDEX('Raw Data Input'!$I:$I,MATCH($E15,'Raw Data Input'!$D:$D,0)),0) -> 3755240 | Y15: =IFERROR(INDEX('Raw Data Input'!$J:$J,MATCH($E15,'Raw Data Input'!$D:$D,0)),0) -> 311659 | Z15: =IFERROR(INDEX('Raw Data Input'!$K:$K,MATCH($E15,'Raw Data Input'!$D:$D,0)),0) -> 3100 | AA15: =IFERROR(INDEX('Raw Data Input'!$L:$L,MATCH($E15,'Raw Data Input'!$D:$D,0)),0) -> 5339861 | AB15: =IFERROR(INDEX('Raw Data Input'!$M:$M,MATCH($E15,'Raw Data Input'!$D:$D,0)),0) -> 1159536 | AC15: =IFERROR(INDEX('Raw Data Input'!$N:$N,MATCH($E15,'Raw Data Input'!$D:$D,0)),0) -> 119081 | AD15: =IFERROR(INDEX('Raw Data Input'!$O:$O,MATCH($E15,'Raw Data Input'!$D:$D,0)),0) -> 576293 | AE15: =IFERROR(INDEX('Raw Data Input'!$P:$P,MATCH($E15,'Raw Data Input'!$D:$D,0)),0) -> 202856 | AF15: =IFERROR(INDEX('Raw Data Input'!$Q:$Q,MATCH($E15,'Raw Data Input'!$D:$D,0)),0) -> 2213142 | AG15: =IFERROR(INDEX('Raw Data Input'!$R:$R,MATCH($E15,'Raw Data Input'!$D:$D,0)),0) -> 0 | AH15: =IFERROR(INDEX('Raw Data Input'!$S:$S,MATCH($E15,'Raw Data Input'!$D:$D,0)),0) -> 4759677 | AI15: =IFERROR(INDEX('Raw Data Input'!$T:$T,MATCH($E15,'Raw Data Input'!$D:$D,0)),0) -> 580184
A16: CLYD | B16: Clydestone (Ghana) Ltd | C16: 2020 | D16: =A16&"-"&C16 -> CLYD-2020 | E16: =A16&"-"&(C16-1) -> CLYD-2019 | F16: =IFERROR(INDEX('Raw Data Input'!$F:$F,MATCH($D16,'Raw Data Input'!$D:$D,0)),0) -> 4039375 | G16: =IFERROR(INDEX('Raw Data Input'!$G:$G,MATCH($D16,'Raw Data Input'!$D:$D,0)),0) -> -2358952 | H16: =IFERROR(INDEX('Raw Data Input'!$H:$H,MATCH($D16,'Raw Data Input'!$D:$D,0)),0) -> 1990637 | I16: =IFERROR(INDEX('Raw Data Input'!$I:$I,MATCH($D16,'Raw Data Input'!$D:$D,0)),0) -> 3080302 | J16: =IFERROR(INDEX('Raw Data Input'!$J:$J,MATCH($D16,'Raw Data Input'!$D:$D,0)),0) -> 162051 | K16: =IFERROR(INDEX('Raw Data Input'!$K:$K,MATCH($D16,'Raw Data Input'!$D:$D,0)),0) -> 24536 | L16: =IFERROR(INDEX('Raw Data Input'!$L:$L,MATCH($D16,'Raw Data Input'!$D:$D,0)),0) -> 6592549 | M16: =IFERROR(INDEX('Raw Data Input'!$M:$M,MATCH($D16,'Raw Data Input'!$D:$D,0)),0) -> 1107547 | N16: =IFERROR(INDEX('Raw Data Input'!$N:$N,MATCH($D16,'Raw Data Input'!$D:$D,0)),0) -> 86948 | O16: =IFERROR(INDEX('Raw Data Input'!$O:$O,MATCH($D16,'Raw Data Input'!$D:$D,0)),0) -> 72139 | P16: =IFERROR(INDEX('Raw Data Input'!$P:$P,MATCH($D16,'Raw Data Input'!$D:$D,0)),0) -> 215325 | Q16: =IFERROR(INDEX('Raw Data Input'!$Q:$Q,MATCH($D16,'Raw Data Input'!$D:$D,0)),0) -> 4759677 | R16: =IFERROR(INDEX('Raw Data Input'!$R:$R,MATCH($D16,'Raw Data Input'!$D:$D,0)),0) -> 0 | S16: =IFERROR(INDEX('Raw Data Input'!$S:$S,MATCH($D16,'Raw Data Input'!$D:$D,0)),0) -> 3450920 | T16: =IFERROR(INDEX('Raw Data Input'!$T:$T,MATCH($D16,'Raw Data Input'!$D:$D,0)),0) -> 3141629 | U16: =IFERROR(INDEX('Raw Data Input'!$F:$F,MATCH($E16,'Raw Data Input'!$D:$D,0)),0) -> 7244821 | V16: =IFERROR(INDEX('Raw Data Input'!$G:$G,MATCH($E16,'Raw Data Input'!$D:$D,0)),0) -> -5322352 | W16: =IFERROR(INDEX('Raw Data Input'!$H:$H,MATCH($E16,'Raw Data Input'!$D:$D,0)),0) -> 2083907 | X16: =IFERROR(INDEX('Raw Data Input'!$I:$I,MATCH($E16,'Raw Data Input'!$D:$D,0)),0) -> 3935378 | Y16: =IFERROR(INDEX('Raw Data Input'!$J:$J,MATCH($E16,'Raw Data Input'!$D:$D,0)),0) -> 235519 | Z16: =IFERROR(INDEX('Raw Data Input'!$K:$K,MATCH($E16,'Raw Data Input'!$D:$D,0)),0) -> 0 | AA16: =IFERROR(INDEX('Raw Data Input'!$L:$L,MATCH($E16,'Raw Data Input'!$D:$D,0)),0) -> 5441358 | AB16: =IFERROR(INDEX('Raw Data Input'!$M:$M,MATCH($E16,'Raw Data Input'!$D:$D,0)),0) -> 1187033 | AC16: =IFERROR(INDEX('Raw Data Input'!$N:$N,MATCH($E16,'Raw Data Input'!$D:$D,0)),0) -> 90072 | AD16: =IFERROR(INDEX('Raw Data Input'!$O:$O,MATCH($E16,'Raw Data Input'!$D:$D,0)),0) -> 224284 | AE16: =IFERROR(INDEX('Raw Data Input'!$P:$P,MATCH($E16,'Raw Data Input'!$D:$D,0)),0) -> 448938 | AF16: =IFERROR(INDEX('Raw Data Input'!$Q:$Q,MATCH($E16,'Raw Data Input'!$D:$D,0)),0) -> 3174611 | AG16: =IFERROR(INDEX('Raw Data Input'!$R:$R,MATCH($E16,'Raw Data Input'!$D:$D,0)),0) -> 0 | AH16: =IFERROR(INDEX('Raw Data Input'!$S:$S,MATCH($E16,'Raw Data Input'!$D:$D,0)),0) -> 4395995 | AI16: =IFERROR(INDEX('Raw Data Input'!$T:$T,MATCH($E16,'Raw Data Input'!$D:$D,0)),0) -> 1045363
... A98: SWL | B98: Sam Wood Ltd | C98: 2020 | D98: =A98&"-"&C98 -> SWL-2020 | E98: =A98&"-"&(C98-1) -> SWL-2019 | F98: =IFERROR(INDEX('Raw Data Input'!$F:$F,MATCH($D98,'Raw Data Input'!$D:$D,0)),0) -> 0 | G98: =IFERROR(INDEX('Raw Data Input'!$G:$G,MATCH($D98,'Raw Data Input'!$D:$D,0)),0) -> -506148 | H98: =IFERROR(INDEX('Raw Data Input'!$H:$H,MATCH($D98,'Raw Data Input'!$D:$D,0)),0) -> 4124 | I98: =IFERROR(INDEX('Raw Data Input'!$I:$I,MATCH($D98,'Raw Data Input'!$D:$D,0)),0) -> 397150 | J98: =IFERROR(INDEX('Raw Data Input'!$J:$J,MATCH($D98,'Raw Data Input'!$D:$D,0)),0) -> 2758815 | K98: =IFERROR(INDEX('Raw Data Input'!$K:$K,MATCH($D98,'Raw Data Input'!$D:$D,0)),0) -> 0 | L98: =IFERROR(INDEX('Raw Data Input'!$L:$L,MATCH($D98,'Raw Data Input'!$D:$D,0)),0) -> 3396210 | M98: =IFERROR(INDEX('Raw Data Input'!$M:$M,MATCH($D98,'Raw Data Input'!$D:$D,0)),0) -> -27516 | N98: =IFERROR(INDEX('Raw Data Input'!$N:$N,MATCH($D98,'Raw Data Input'!$D:$D,0)),0) -> 369956 | O98: =IFERROR(INDEX('Raw Data Input'!$O:$O,MATCH($D98,'Raw Data Input'!$D:$D,0)),0) -> -533664 | P98: =IFERROR(INDEX('Raw Data Input'!$P:$P,MATCH($D98,'Raw Data Input'!$D:$D,0)),0) -> -592 | Q98: =IFERROR(INDEX('Raw Data Input'!$Q:$Q,MATCH($D98,'Raw Data Input'!$D:$D,0)),0) -> 4650055 | R98: =IFERROR(INDEX('Raw Data Input'!$R:$R,MATCH($D98,'Raw Data Input'!$D:$D,0)),0) -> 0 | S98: =IFERROR(INDEX('Raw Data Input'!$S:$S,MATCH($D98,'Raw Data Input'!$D:$D,0)),0) -> 4838164 | T98: =IFERROR(INDEX('Raw Data Input'!$T:$T,MATCH($D98,'Raw Data Input'!$D:$D,0)),0) -> -1441954 | U98: =IFERROR(INDEX('Raw Data Input'!$F:$F,MATCH($E98,'Raw Data Input'!$D:$D,0)),0) -> 454180 | V98: =IFERROR(INDEX('Raw Data Input'!$G:$G,MATCH($E98,'Raw Data Input'!$D:$D,0)),0) -> -424377 | W98: =IFERROR(INDEX('Raw Data Input'!$H:$H,MATCH($E98,'Raw Data Input'!$D:$D,0)),0) -> 4124 | X98: =IFERROR(INDEX('Raw Data Input'!$I:$I,MATCH($E98,'Raw Data Input'!$D:$D,0)),0) -> 545971 | Y98: =IFERROR(INDEX('Raw Data Input'!$J:$J,MATCH($E98,'Raw Data Input'!$D:$D,0)),0) -> 3025809 | Z98: =IFERROR(INDEX('Raw Data Input'!$K:$K,MATCH($E98,'Raw Data Input'!$D:$D,0)),0) -> 0 | AA98: =IFERROR(INDEX('Raw Data Input'!$L:$L,MATCH($E98,'Raw Data Input'!$D:$D,0)),0) -> 3914988 | AB98: =IFERROR(INDEX('Raw Data Input'!$M:$M,MATCH($E98,'Raw Data Input'!$D:$D,0)),0) -> -813627 | AC98: =IFERROR(INDEX('Raw Data Input'!$N:$N,MATCH($E98,'Raw Data Input'!$D:$D,0)),0) -> 378867 | AD98: =IFERROR(INDEX('Raw Data Input'!$O:$O,MATCH($E98,'Raw Data Input'!$D:$D,0)),0) -> -1265083 | AE98: =IFERROR(INDEX('Raw Data Input'!$P:$P,MATCH($E98,'Raw Data Input'!$D:$D,0)),0) -> -478025 | AF98: =IFERROR(INDEX('Raw Data Input'!$Q:$Q,MATCH($E98,'Raw Data Input'!$D:$D,0)),0) -> 4635169 | AG98: =IFERROR(INDEX('Raw Data Input'!$R:$R,MATCH($E98,'Raw Data Input'!$D:$D,0)),0) -> 0 | AH98: =IFERROR(INDEX('Raw Data Input'!$S:$S,MATCH($E98,'Raw Data Input'!$D:$D,0)),0) -> 4823278 | AI98: =IFERROR(INDEX('Raw Data Input'!$T:$T,MATCH($E98,'Raw Data Input'!$D:$D,0)),0) -> -908290

Sheet M-Score & Ratios
A1: Beneish M-Score and Financial Ratios by Firm-Year
A2: Calculated automatically from 'Raw Data Input'. Do not type values directly into this sheet.
A4: Symbol | B4: Company | C4: Fiscal Year | D4: DSRI | E4: GMI | F4: AQI | G4: SGI | H4: DEPI | I4: SGAI | J4: TATA | K4: LVGI | L4: M-Score | M4: Classification (threshold −2.22) | N4: ROA | O4: Current Ratio | P4: Debt-to- Equity | Q4: Asset Growth
A5: ALW | B5: Aluworks Ltd | C5: 2019 | D5: =IFERROR(IF(Lookups!U5=0,1,IF(Lookups!W5=0,1,(Lookups!H5/Lookups!F5)/(Lookups!W5/Lookups!U5))),1) -> 1.0778753 | E5: =IFERROR(IF(Lookups!U5=0,1,IF(Lookups!F5=0,1,((Lookups!U5-Lookups!V5)/Lookups!U5)/((Lookups!F5-Lookups!G5)/Lookups!F5))),1) -> 1.0453476 | F5: =IFERROR(IF(Lookups!AA5=0,1,IF((1-(Lookups!X5+Lookups!Y5+Lookups!Z5)/Lookups!AA5)=0,1,(1-(Lookups!I5+Lookups!J5+Lookups!K5)/Lookups!L5)/(1-(Lookups!X5+Lookups!Y5+Lookups!Z5)/Lookups!AA5))),1) -> 0 | G5: =IFERROR(IF(Lookups!U5=0,1,Lookups!F5/Lookups!U5),1) -> 1.2319866 | H5: =IFERROR(IF((Lookups!Y5+Lookups!AC5)=0,1,IF((Lookups!J5+Lookups!N5)=0,1,(Lookups!AC5/(Lookups!Y5+Lookups!AC5))/(Lookups!N5/(Lookups!J5+Lookups!N5)))),1) -> 0.73556273 | I5: =IFERROR(IF(Lookups!U5=0,1,IF(Lookups!AB5=0,1,(Lookups!M5/Lookups!F5)/(Lookups!AB5/Lookups!U5))),1) -> 0.70825532 | J5: =IFERROR(IF(Lookups!L5=0,1,(Lookups!O5-Lookups!P5)/Lookups!L5),1) -> 0.09484143 | K5: =IFERROR(IF(Lookups!AA5=0,1,IF((Lookups!AF5+Lookups!AG5)=0,1,((Lookups!Q5+Lookups!R5)/Lookups!L5)/((Lookups!AF5+Lookups!AG5)/Lookups!AA5))),1) -> 1.2246166 | L5: =IFERROR(-4.84+0.92*D5+0.528*E5+0.404*F5+0.892*G5+0.115*H5-0.172*I5+4.679*J5-0.327*K5,"") -> -2.1913959 | M5: =IF(L5="","",IF(L5>-2.22,"Likely Manipulator","Non-Manipulator")) -> Likely Manipulator | N5: =IFERROR(Lookups!O5/Lookups!L5,"") -> 0.10705106 | O5: =IFERROR(Lookups!I5/Lookups!Q5,"") -> 0.12563793 | P5: =IFERROR(Lookups!S5/Lookups!T5,"") -> 10.450258 | Q5: =IFERROR((Lookups!L5-Lookups!AA5)/Lookups!AA5,"") -> -0.017737569
A6: ALW | B6: Aluworks Ltd | C6: 2020 | D6: =IFERROR(IF(Lookups!U6=0,1,IF(Lookups!W6=0,1,(Lookups!H6/Lookups!F6)/(Lookups!W6/Lookups!U6))),1) -> 0.60583176 | E6: =IFERROR(IF(Lookups!U6=0,1,IF(Lookups!F6=0,1,((Lookups!U6-Lookups!V6)/Lookups!U6)/((Lookups!F6-Lookups!G6)/Lookups!F6))),1) -> 0.96564732 | F6: =IFERROR(IF(Lookups!AA6=0,1,IF((1-(Lookups!X6+Lookups!Y6+Lookups!Z6)/Lookups!AA6)=0,1,(1-(Lookups!I6+Lookups!J6+Lookups!K6)/Lookups!L6)/(1-(Lookups!X6+Lookups!Y6+Lookups!Z6)/Lookups!AA6))),1) -> 1 | G6: =IFERROR(IF(Lookups!U6=0,1,Lookups!F6/Lookups!U6),1) -> 0.89586066 | H6: =IFERROR(IF((Lookups!Y6+Lookups!AC6)=0,1,IF((Lookups!J6+Lookups!N6)=0,1,(Lookups!AC6/(Lookups!Y6+Lookups!AC6))/(Lookups!N6/(Lookups!J6+Lookups!N6)))),1) -> 1.0101743 | I6: =IFERROR(IF(Lookups!U6=0,1,IF(Lookups!AB6=0,1,(Lookups!M6/Lookups!F6)/(Lookups!AB6/Lookups!U6))),1) -> 0.88351812 | J6: =IFERROR(IF(Lookups!L6=0,1,(Lookups!O6-Lookups!P6)/Lookups!L6),1) -> -0.13444879 | K6: =IFERROR(IF(Lookups!AA6=0,1,IF((Lookups!AF6+Lookups!AG6)=0,1,((Lookups!Q6+Lookups!R6)/Lookups!L6)/((Lookups!AF6+Lookups!AG6)/Lookups!AA6))),1) -> 1.2257944 | L6: =IFERROR(-4.84+0.92*D6+0.528*E6+0.404*F6+0.892*G6+0.115*H6-0.172*I6+4.679*J6-0.327*K6,"") -> -3.635381 | M6: =IF(L6="","",IF(L6>-2.22,"Likely Manipulator","Non-Manipulator")) -> Non-Manipulator | N6: =IFERROR(Lookups!O6/Lookups!L6,"") -> -0.15689096 | O6: =IFERROR(Lookups!I6/Lookups!Q6,"") -> 0.083861773 | P6: =IFERROR(Lookups!S6/Lookups!T6,"") -> -15.66989 | Q6: =IFERROR((Lookups!L6-Lookups!AA6)/Lookups!AA6,"") -> -0.047126533
